File: Elasticidad Módulo de Young/masdatajic.txt
Time (s) Run #1	Position (m) Run #1	Force (N) Run #1	Stress (MPa) Run #1	Strain Run #1	Time (s) Run #2	Position (m) Run #2	Force (N) Run #2	Stress (MPa) Run #2	Strain Run #2	Time (s) Run #3	Position (m) Run #3	Force (N) Run #3	Stress (MPa) Run #3	Strain Run #3	Time (s) Run #4	Position (m) Run #4	Force (N) Run #4	Stress (MPa) Run #4	Strain Run #4	Time (s) Run #5	Position (m) Run #5	Force (N) Run #5	Stress (MPa) Run #5	Strain Run #5	Time (s) Run #6	Position (m) Run #6	Force (N) Run #6	Stress (MPa) Run #6	Strain Run #6
0.000	5.22745E-7	0	12.43	1.49E-5	0.000	4.80576E-7	0	12.46	1.37E-5	0.000	4.80576E-7	0	12.46	1.37E-5	0.000	4.38414E-7	0	12.49	1.25E-5	0.000	4.80576E-7	0	12.46	1.37E-5	0.000	5.22745E-7	0	12.43	1.49E-5
1.000	6.49289E-7	-1	12.34	1.86E-5	1.000	4.80576E-7	0	12.46	1.37E-5	1.000	5.22745E-7	0	12.43	1.49E-5	1.000	4.80576E-7	0	12.46	1.37E-5	1.000	5.22745E-7	0	12.43	1.49E-5	1.000	5.64920E-7	0	12.40	1.61E-5
2.000	3.06274E-6	0	12.43	8.75E-5						2.000	5.22745E-7	0	12.43	1.49E-5	2.000	5.22745E-7	0	12.43	1.49E-5	2.000	5.22745E-7	0	12.43	1.49E-5	2.000	1.29055E-5	203	37.64	3.69E-4
3.000	1.14282E-4	25	15.55	0.00						3.000	5.64920E-7	0	12.40	1.61E-5	3.000	5.22745E-7	0	12.43	1.49E-5	3.000	9.83127E-5	0	12.43	0.00	3.000	6.86500E-5	1689	222.43	0.00
4.000	1.47149E-4	30	16.12	0.00						4.000	7.25917E-5	13	14.02	0.00	4.000	4.80576E-7	0	12.46	1.37E-5	4.000	7.09141E-4	0	12.46	0.02	4.000	2.52922E-4	3051	391.84	0.01
5.000	1.79854E-4	35	16.80	0.01						5.000	2.62709E-4	37	17.04	0.01	5.000	5.22745E-7	0	12.43	1.49E-5	5.000	0.00121	0	12.49	0.03	5.000	5.43661E-4	3246	416.08	0.02
6.000	2.08364E-4	39	17.31	0.01						6.000	5.19946E-4	55	19.32	0.01						6.000	0.00158	0	12.43	0.05	6.000	7.63888E-4	3412	436.71	0.02
7.000	2.37510E-4	43	17.82	0.01						7.000	7.42410E-4	62	20.10	0.02						7.000	0.00212	0	12.43	0.06	7.000	9.97111E-4	3533	451.70	0.03
8.000	2.56396E-4	44	17.94	0.01						8.000	0.00103	68	20.93	0.03						8.000	0.00258	1	12.52	0.07	8.000	0.00122	3675	469.33	0.03
9.000	2.70755E-4	46	18.12	0.01						9.000	0.00127	68	20.90	0.04						9.000	0.00319	0	12.46	0.09	9.000	0.00144	3768	480.95	0.04
10.000	2.85237E-4	46	18.21	0.01						10.000	0.00150	68	20.93	0.04						10.000	0.00384	0	12.49	0.11	10.000	0.00168	3853	491.48	0.05
11.000	3.04431E-4	49	18.57	0.01						11.000	0.00171	68	20.93	0.05						11.000	0.00450	0	12.46	0.13	11.000	0.00189	3911	498.75	0.05
12.000	3.19467E-4	51	18.72	0.01						12.000	0.00192	67	20.81	0.05						12.000	0.00512	14	14.14	0.15	12.000	0.00219	4004	510.34	0.06
13.000	3.32720E-4	51	18.78	0.01						13.000	0.00217	69	21.05	0.06						13.000	0.00525	1829	239.91	0.15	13.000	0.00240	4037	514.41	0.07
14.000	3.45298E-4	52	18.87	0.01						14.000	0.00240	67	20.72	0.07						14.000	0.00525	2024	264.09	0.15	14.000	0.00259	4083	520.15	0.07
15.000	3.71153E-4	57	19.47	0.01						15.000	0.00260	64	20.43	0.07						15.000	0.00525	2020	263.56	0.15	15.000	0.00279	4130	525.99	0.08
16.000	3.90675E-4	58	19.59	0.01						16.000	0.00285	65	20.58	0.08						16.000	0.00522	1615	213.18	0.15	16.000	0.00305	4146	527.97	0.09
17.000	4.13804E-4	60	19.86	0.01						17.000	0.00311	64	20.40	0.09						17.000	0.00476	1	12.52	0.14	17.000	0.00326	4182	532.40	0.09
18.000	4.47999E-4	64	20.40	0.01						18.000	0.00333	61	20.01	0.10						18.000	0.00460	1	12.58	0.13	18.000	0.00348	4171	531.02	0.10
19.000	4.80372E-4	68	20.87	0.01						19.000	0.00357	57	19.56	0.10						19.000	0.00469	1	12.55	0.13	19.000	0.00368	4202	534.97	0.11
20.000	5.15367E-4	71	21.29	0.01						20.000	0.00381	53	18.99	0.11						20.000	0.00481	1	12.55	0.14	20.000	0.00394	4192	533.68	0.11
21.000	5.50998E-4	75	21.71	0.02						21.000	0.00399	49	18.48	0.11						21.000	0.00491	1	12.55	0.14	21.000	0.00415	4058	516.95	0.12
22.000	5.84372E-4	76	21.92	0.02						22.000	0.00420	43	17.79	0.12						22.000	0.00498	1	12.55	0.14	22.000	0.00479	-76	2.98	0.14
23.000	6.18775E-4	79	22.31	0.02						23.000	0.00442	39	17.22	0.13						23.000	0.00507	1	12.55	0.14	23.000	0.00482	-76	3.01	0.14
24.000	6.50124E-4	82	22.61	0.02						24.000	0.00468	33	16.56	0.13						24.000	0.00511	16	14.38	0.15	24.000	0.00482	-76	2.98	0.14
25.000	6.84689E-4	84	22.88	0.02						25.000	0.00489	27	15.76	0.14						25.000	0.00513	22	15.16	0.15	25.000	0.00482	-76	3.01	0.14
26.000	7.21199E-4	86	23.12	0.02						26.000	0.00514	24	15.46	0.15						26.000	0.00518	182	35.03	0.15
27.000	7.66876E-4	90	23.63	0.02						27.000	0.00540	20	14.89	0.15						27.000	0.00518	249	43.35	0.15
28.000	8.08308E-4	93	23.99	0.02						28.000	0.00563	15	14.29	0.16						28.000	0.00505	1	12.52	0.14
29.000	8.44860E-4	95	24.20	0.02						29.000	0.00585	13	13.99	0.17						29.000	0.00491	0	12.46	0.14
30.000	8.70300E-4	94	24.17	0.02						30.000	0.00609	11	13.75	0.17						30.000	0.00482	1	12.52	0.14
31.000	8.99351E-4	95	24.29	0.03						31.000	0.00631	7	13.27	0.18						31.000	0.00490	1	12.55	0.14
32.000	9.33244E-4	98	24.59	0.03						32.000	0.00654	8	13.42	0.19						32.000	0.00495	1	12.58	0.14
33.000	9.44436E-4	95	24.29	0.03						33.000	0.00676	7	13.27	0.19						33.000	0.00496	1	12.61	0.14
34.000	9.60390E-4	95	24.23	0.03						34.000	0.00698	3	12.85	0.20						34.000	0.00497	1	12.58	0.14
35.000	9.62138E-4	92	23.87	0.03						35.000	0.00722	5	13.00	0.21						35.000	0.00497	0	12.49	0.14
36.000	9.62257E-4	91	23.78	0.03						36.000	0.00740	3	12.82	0.21						36.000	0.00497	1	12.55	0.14
37.000	9.45870E-4	87	23.21	0.03						37.000	0.00766	6	13.15	0.22						37.000	0.00497	1	12.55	0.14
38.000	9.28294E-4	82	22.58	0.03						38.000	0.00793	6	13.12	0.23						38.000	0.00497	1	12.55	0.14
39.000	9.16075E-4	79	22.22	0.03						39.000	0.00816	3	12.79	0.23						39.000	0.00497	1	12.52	0.14
40.000	8.97708E-4	75	21.71	0.03						40.000	0.00836	3	12.79	0.24						40.000	0.00497	1	12.58	0.14
41.000	8.75453E-4	71	21.26	0.03						41.000	0.00862	5	13.06	0.25						41.000	0.00497	1	12.55	0.14
42.000	8.59588E-4	67	20.78	0.02						42.000	0.00886	5	13.03	0.25						42.000	0.00497	1	12.58	0.14
43.000	8.42253E-4	65	20.46	0.02						43.000	0.00905	3	12.79	0.26						43.000	0.00497	1	12.52	0.14
44.000	8.07113E-4	58	19.68	0.02						44.000	0.00929	7	13.27	0.27						44.000	0.00497	1	12.58	0.14
45.000	7.55445E-4	48	18.45	0.02						45.000	0.00955	5	13.06	0.27						45.000	0.00497	1	12.52	0.14
46.000	7.23039E-4	45	18.00	0.02						46.000	0.00978	4	12.97	0.28						46.000	0.00497	1	12.52	0.14
47.000	6.88424E-4	39	17.31	0.02						47.000	0.00998	3	12.82	0.29						47.000	0.00497	1	12.52	0.14
48.000	6.63641E-4	36	16.86	0.02						48.000	0.01022	3	12.85	0.29						48.000	0.00497	1	12.55	0.14
49.000	6.41318E-4	32	16.47	0.02						49.000	0.01044	4	12.91	0.30						49.000	0.00497	1	12.55	0.14
50.000	6.07262E-4	27	15.85	0.02						50.000	0.01065	3	12.85	0.30						50.000	0.00497	1	12.58	0.14
51.000	5.81683E-4	25	15.52	0.02						51.000	0.01090	6	13.15	0.31						51.000	0.00497	1	12.55	0.14
52.000	5.57541E-4	21	15.07	0.02						52.000	0.01114	5	13.03	0.32						52.000	0.00497	1	12.55	0.14
53.000	5.16674E-4	15	14.32	0.01						53.000	0.01138	6	13.15	0.33						53.000	0.00497	1	12.55	0.14
54.000	4.98426E-4	14	14.20	0.01						54.000	0.01159	4	12.97	0.33						54.000	0.00497	1	12.55	0.14
55.000	4.98175E-4	16	14.38	0.01						55.000	0.01183	6	13.21	0.34						55.000	0.00497	1	12.52	0.14
56.000	4.97925E-4	17	14.56	0.01						56.000	0.01203	4	12.91	0.34						56.000	0.00498	1	12.58	0.14
57.000	4.97716E-4	18	14.71	0.01						57.000	0.01228	6	13.21	0.35						57.000	0.00499	1	12.58	0.14
58.000	4.97675E-4	19	14.74	0.01						58.000	0.01250	5	13.06	0.36						58.000	0.00499	1	12.58	0.14
59.000	4.97633E-4	19	14.77	0.01						59.000	0.01275	6	13.12	0.36						59.000	0.00499	1	12.55	0.14
60.000	4.97591E-4	19	14.80	0.01						60.000	0.01299	6	13.21	0.37						60.000	0.00501	1	12.58	0.14
61.000	4.97425E-4	20	14.92	0.01						61.000	0.01320	4	12.88	0.38						61.000	0.00505	1	12.55	0.14
62.000	5.43265E-4	30	16.21	0.02						62.000	0.01339	4	12.88	0.38						62.000	0.00508	8	13.39	0.15
63.000	5.94156E-4	41	17.52	0.02						63.000	0.01365	6	13.24	0.39						63.000	0.00510	13	14.11	0.15
64.000	6.37888E-4	49	18.51	0.02						64.000	0.01394	7	13.33	0.40						64.000	0.00513	20	14.95	0.15
65.000	6.96542E-4	59	19.74	0.02						65.000	0.01415	6	13.12	0.40						65.000	0.00515	27	15.85	0.15
66.000	7.54098E-4	68	20.84	0.02						66.000	0.01437	6	13.18	0.41						66.000	0.00517	58	19.59	0.15
67.000	8.13133E-4	75	21.80	0.02						67.000	0.01460	6	13.15	0.42						67.000	0.00517	80	22.37	0.15
68.000	8.68364E-4	83	22.76	0.02						68.000	0.01485	-2	12.22	0.42						68.000	0.00518	88	23.33	0.15
69.000	9.15865E-4	88	23.33	0.03						69.000	0.01506	6	13.15	0.43						69.000	0.00518	98	24.68	0.15
70.000	9.48962E-4	91	23.75	0.03						70.000	0.01531	6	13.24	0.44						70.000	0.00518	113	26.50	0.15
71.000	9.76227E-4	91	23.78	0.03						71.000	0.01556	6	13.21	0.44						71.000	0.00518	101	24.98	0.15
72.000	9.95158E-4	92	23.87	0.03						72.000	0.01578	5	13.03	0.45						72.000	0.00515	21	15.10	0.15
73.000	0.00101	92	23.93	0.03						73.000	0.01596	3	12.85	0.46						73.000	0.00514	20	14.95	0.15
74.000	0.00103	94	24.14	0.03						74.000	0.01618	6	13.15	0.46						74.000	0.00514	20	14.92	0.15
75.000	0.00106	95	24.23	0.03						75.000	0.01641	6	13.18	0.47						75.000	0.00513	17	14.53	0.15
76.000	0.00108	98	24.59	0.03						76.000	0.01664	6	13.15	0.48						76.000	0.00512	17	14.53	0.15
77.000	0.00110	98	24.59	0.03						77.000	0.01685	6	13.18	0.48						77.000	0.00510	8	13.39	0.15
78.000	0.00110	95	24.20	0.03						78.000	0.01709	7	13.33	0.49						78.000	0.00510	8	13.45	0.15
79.000	0.00106	83	22.79	0.03						79.000	0.01736	9	13.51	0.50						79.000	0.00510	8	13.48	0.15
80.000	0.00102	75	21.80	0.03						80.000	0.01759	6	13.21	0.50						80.000	0.00510	8	13.42	0.15
81.000	9.84874E-4	70	21.11	0.03						81.000	0.01782	7	13.33	0.51						81.000	0.00510	8	13.39	0.15
82.000	9.35018E-4	60	19.95	0.03						82.000	0.01804	7	13.33	0.52						82.000	0.00510	8	13.45	0.15
83.000	9.14509E-4	58	19.62	0.03						83.000	0.01829	6	13.24	0.52						83.000	0.00510	8	13.42	0.15
84.000	8.94002E-4	55	19.29	0.03						84.000	0.01854	9	13.54	0.53						84.000	0.00510	8	13.48	0.15
85.000	8.65055E-4	50	18.63	0.02						85.000	0.01876	7	13.27	0.54						85.000	0.00510	8	13.45	0.15
86.000	8.35229E-4	46	18.15	0.02						86.000	0.01904	9	13.57	0.54						86.000	0.00510	8	13.39	0.15
87.000	7.75525E-4	35	16.77	0.02						87.000	0.01928	8	13.39	0.55						87.000	0.00510	8	13.42	0.15
88.000	7.25330E-4	28	15.88	0.02						88.000	0.01955	8	13.48	0.56						88.000	0.00510	8	13.39	0.15
89.000	6.83782E-4	22	15.16	0.02						89.000	0.01984	9	13.57	0.57						89.000	0.00510	8	13.39	0.15
90.000	6.40841E-4	17	14.53	0.02						90.000	0.02007	6	13.18	0.57						90.000	0.00510	8	13.45	0.15
91.000	6.17045E-4	15	14.29	0.02						91.000	0.02034	9	13.54	0.58						91.000	0.00510	8	13.48	0.15
92.000	6.16753E-4	17	14.50	0.02						92.000	0.02060	8	13.45	0.59						92.000	0.00510	9	13.51	0.15
93.000	6.16503E-4	18	14.68	0.02						93.000	0.02085	7	13.27	0.60						93.000	0.00510	8	13.42	0.15
94.000	6.17523E-4	19	14.86	0.02						94.000	0.02112	8	13.39	0.60						94.000	0.00510	8	13.45	0.15
95.000	6.21125E-4	21	15.01	0.02						95.000	0.02139	9	13.60	0.61						95.000	0.00510	8	13.42	0.15
96.000	6.25195E-4	23	15.28	0.02						96.000	0.02172	10	13.63	0.62						96.000	0.00510	8	13.42	0.15
97.000	6.28839E-4	24	15.40	0.02						97.000	0.02199	9	13.54	0.63						97.000	0.00510	8	13.42	0.15
98.000	6.31296E-4	24	15.46	0.02						98.000	0.02227	8	13.39	0.64						98.000	0.00510	8	13.48	0.15
99.000	6.37314E-4	26	15.70	0.02						99.000	0.02257	9	13.51	0.64						99.000	0.00510	8	13.48	0.15
100.000	6.57565E-4	30	16.21	0.02						100.000	0.02282	7	13.33	0.65						100.000	0.00510	8	13.48	0.15
101.000	7.05669E-4	42	17.70	0.02						101.000	0.02308	7	13.36	0.66						101.000	0.00510	9	13.51	0.15
102.000	7.29184E-4	46	18.15	0.02						102.000	0.02332	8	13.42	0.67						102.000	0.00510	8	13.42	0.15
103.000	7.57617E-4	51	18.72	0.02						103.000	0.02352	6	13.18	0.67						103.000	0.00510	9	13.51	0.15
104.000	8.56131E-4	69	20.99	0.02						104.000	0.02379	9	13.51	0.68						104.000	0.00510	8	13.42	0.15
105.000	8.77600E-4	70	21.08	0.03						105.000	0.02405	8	13.48	0.69						105.000	0.00510	8	13.45	0.15
106.000	9.11245E-4	73	21.56	0.03						106.000	0.02426	6	13.12	0.69						106.000	0.00510	8	13.45	0.15
107.000	9.56515E-4	80	22.37	0.03						107.000	0.02443	4	12.97	0.70						107.000	0.00510	8	13.45	0.15
108.000	9.85204E-4	83	22.76	0.03						108.000	0.02470	9	13.54	0.71						108.000	0.00510	8	13.45	0.15
109.000	0.00101	86	23.09	0.03						109.000	0.02498	10	13.72	0.71						109.000	0.00510	8	13.48	0.15
110.000	0.00104	88	23.36	0.03						110.000	0.02520	7	13.33	0.72						110.000	0.00510	8	13.45	0.15
111.000	0.00106	90	23.60	0.03						111.000	0.02551	12	13.87	0.73						111.000	0.00510	8	13.48	0.15
112.000	0.00109	92	23.90	0.03						112.000	0.02586	11	13.84	0.74						112.000	0.00510	8	13.45	0.15
113.000	0.00111	93	24.05	0.03						113.000	0.02609	8	13.45	0.75						113.000	0.00510	9	13.51	0.15
114.000	0.00112	93	23.96	0.03						114.000	0.02636	11	13.75	0.75						114.000	0.00510	8	13.45	0.15
115.000	0.00113	93	23.96	0.03						115.000	0.02656	5	13.09	0.76						115.000	0.00510	8	13.45	0.15
116.000	0.00113	92	23.90	0.03						116.000	0.02683	9	13.57	0.77						116.000	0.00510	9	13.51	0.15
117.000	0.00114	92	23.87	0.03						117.000	0.02708	10	13.72	0.77						117.000	0.00510	9	13.51	0.15
118.000	0.00115	91	23.78	0.03						118.000	0.02739	12	13.93	0.78						118.000	0.00510	9	13.60	0.15
119.000	0.00118	94	24.17	0.03						119.000	0.02765	10	13.63	0.79						119.000	0.00514	24	15.37	0.15
120.000	0.00121	98	24.62	0.03						120.000	0.02787	8	13.39	0.80						120.000	0.00517	51	18.75	0.15
121.000	0.00122	97	24.56	0.03						121.000	0.02818	12	13.87	0.81						121.000	0.00517	78	22.13	0.15
122.000	0.00112	75	21.77	0.03						122.000	0.02848	12	13.87	0.81						122.000	0.00518	83	22.73	0.15
123.000	0.00104	62	20.13	0.03						123.000	0.02878	12	13.96	0.82						123.000	0.00518	91	23.81	0.15
124.000	9.93901E-4	54	19.14	0.03						124.000	0.02909	11	13.84	0.83						124.000	0.00518	101	25.03	0.15
125.000	9.38263E-4	45	18.03	0.03						125.000	0.02936	9	13.60	0.84						125.000	0.00517	43	17.82	0.15
126.000	8.66495E-4	34	16.65	0.02						126.000	0.02967	12	13.87	0.85						126.000	0.00514	19	14.80	0.15
127.000	7.50312E-4	15	14.35	0.02						127.000	0.03000	12	13.90	0.86						127.000	0.00512	15	14.35	0.15
128.000	7.32916E-4	17	14.53	0.02						128.000	0.03030	11	13.78	0.87						128.000	0.00512	15	14.29	0.15
129.000	7.32458E-4	19	14.86	0.02						129.000	0.03062	11	13.78	0.87						129.000	0.00511	11	13.81	0.15
130.000	7.32125E-4	21	15.10	0.02						130.000	0.03091	11	13.81	0.88						130.000	0.00511	10	13.72	0.15
131.000	7.31958E-4	22	15.22	0.02						131.000	0.03123	12	13.93	0.89						131.000	0.00510	6	13.18	0.15
132.000	7.04893E-4	17	14.59	0.02						132.000	0.03150	10	13.72	0.90						132.000	0.00509	6	13.12	0.15
133.000	6.99771E-4	18	14.62	0.02						133.000	0.03180	12	13.93	0.91						133.000	0.00512	16	14.47	0.15
134.000	6.89736E-4	17	14.53	0.02						134.000	0.03210	13	13.99	0.92						134.000	0.00512	19	14.74	0.15
135.000	6.81565E-4	16	14.47	0.02						135.000	0.03238	11	13.78	0.93						135.000	0.00513	21	15.04	0.15
136.000	6.72249E-4	15	14.32	0.02						136.000	0.03270	11	13.78	0.93						136.000	0.00514	25	15.49	0.15
137.000	6.71998E-4	17	14.50	0.02						137.000	0.03303	12	13.96	0.94						137.000	0.00516	31	16.27	0.15
138.000	6.71831E-4	18	14.62	0.02						138.000	0.03330	11	13.75	0.95						138.000	0.00517	58	19.62	0.15
139.000	6.71790E-4	18	14.65	0.02						139.000	0.03355	9	13.51	0.96						139.000	0.00518	81	22.52	0.15
140.000	6.71706E-4	18	14.71	0.02						140.000	0.03381	10	13.66	0.97						140.000	0.00518	101	24.98	0.15
141.000	6.71623E-4	19	14.77	0.02						141.000	0.03410	12	13.90	0.97						141.000	0.00518	100	24.89	0.15
142.000	6.71498E-4	19	14.86	0.02						142.000	0.03439	12	13.96	0.98						142.000	0.00518	97	24.50	0.15
143.000	6.71498E-4	19	14.86	0.02						143.000	0.03466	10	13.66	0.99						143.000	0.00518	51	18.81	0.15
144.000	6.80013E-4	22	15.13	0.02						144.000	0.03498	14	14.17	1.00						144.000	0.00517	31	16.33	0.15
145.000	7.59461E-4	40	17.37	0.02						145.000	0.03527	12	13.87	1.01						145.000	0.00516	23	15.31	0.15
146.000	8.35192E-4	54	19.11	0.02						146.000	0.03553	11	13.81	1.02						146.000	0.00515	21	15.10	0.15
147.000	9.13604E-4	67	20.75	0.03						147.000	0.03580	12	13.90	1.02						147.000	0.00515	20	14.98	0.15
148.000	9.87991E-4	78	22.10	0.03						148.000	0.03606	11	13.78	1.03						148.000	0.00514	19	14.80	0.15
149.000	0.00104	84	22.82	0.03						149.000	0.03627	9	13.60	1.04						149.000	0.00513	18	14.65	0.15
150.000	0.00108	88	23.33	0.03						150.000	0.03653	11	13.84	1.04						150.000	0.00512	15	14.29	0.15
151.000	0.00112	91	23.81	0.03						151.000	0.03679	11	13.84	1.05						151.000	0.00512	16	14.38	0.15
152.000	0.00114	92	23.93	0.03						152.000	0.03708	12	13.93	1.06						152.000	0.00512	14	14.23	0.15
153.000	0.00116	94	24.14	0.03						153.000	0.03732	12	13.93	1.07						153.000	0.00512	15	14.35	0.15
154.000	0.00117	91	23.78	0.03						154.000	0.03757	12	13.96	1.07						154.000	0.00512	17	14.50	0.15
155.000	0.00117	90	23.63	0.03						155.000	0.03783	12	13.87	1.08						155.000	0.00513	18	14.65	0.15
156.000	0.00112	79	22.25	0.03						156.000	0.03804	10	13.69	1.09						156.000	0.00513	20	14.92	0.15
157.000	0.00109	71	21.26	0.03						157.000	0.03832	13	14.08	1.09						157.000	0.00515	24	15.46	0.15
158.000	0.00104	64	20.34	0.03						158.000	0.03858	13	14.02	1.10						158.000	0.00517	47	18.24	0.15
159.000	0.00100	57	19.53	0.03						159.000	0.03887	14	14.20	1.11						159.000	0.00517	66	20.61	0.15
160.000	9.70219E-4	51	18.81	0.03						160.000	0.03913	13	14.05	1.12						160.000	0.00518	92	23.84	0.15
161.000	9.30008E-4	45	18.03	0.03						161.000	0.03941	13	14.08	1.13						161.000	0.00518	110	26.05	0.15
162.000	8.97092E-4	41	17.49	0.03						162.000	0.03961	11	13.81	1.13						162.000	0.00518	108	25.90	0.15
163.000	8.49170E-4	31	16.33	0.02						163.000	0.03984	11	13.84	1.14						163.000	0.00518	107	25.78	0.15
164.000	8.03850E-4	25	15.58	0.02						164.000	0.04004	11	13.78	1.14						164.000	0.00518	107	25.78	0.15
165.000	7.59211E-4	19	14.80	0.02						165.000	0.04029	13	14.08	1.15						165.000	0.00518	107	25.78	0.15
166.000	7.07885E-4	11	13.81	0.02						166.000	0.04052	13	14.08	1.16						166.000	0.00518	108	25.81	0.15
167.000	7.07383E-4	14	14.17	0.02						167.000	0.04076	13	14.02	1.16						167.000	0.00518	107	25.72	0.15
168.000	7.40807E-4	23	15.25	0.02						168.000	0.04103	13	14.11	1.17						168.000	0.00518	107	25.75	0.15
169.000	7.79955E-4	31	16.33	0.02						169.000	0.04124	11	13.84	1.18						169.000	0.00518	108	25.81	0.15
170.000	8.28818E-4	43	17.73	0.02						170.000	0.04151	14	14.14	1.19						170.000	0.00518	108	25.81	0.15
171.000	8.92382E-4	53	19.08	0.03						171.000	0.04177	14	14.17	1.19						171.000	0.00518	107	25.78	0.15
172.000	9.36882E-4	61	19.98	0.03						172.000	0.04201	12	13.96	1.20						172.000	0.00518	107	25.78	0.15
173.000	0.00100	72	21.35	0.03						173.000	0.04220	11	13.84	1.21						173.000	0.00518	108	25.81	0.15
174.000	0.00105	77	22.01	0.03						174.000	0.04246	14	14.14	1.21						174.000	0.00518	108	25.81	0.15
175.000	0.00109	82	22.61	0.03						175.000	0.04271	13	14.11	1.22						175.000	0.00518	107	25.75	0.15
176.000	0.00112	87	23.30	0.03						176.000	0.04290	10	13.72	1.23						176.000	0.00518	107	25.75	0.15
177.000	0.00117	93	23.96	0.03						177.000	0.04315	13	14.05	1.23						177.000	0.00518	107	25.78	0.15
178.000	0.00122	98	24.59	0.03						178.000	0.04337	12	13.90	1.24						178.000	0.00518	107	25.75	0.15
179.000	0.00123	96	24.38	0.04						179.000	0.04361	13	13.99	1.25						179.000	0.00518	107	25.78	0.15
180.000	0.00117	80	22.40	0.03						180.000	0.04387	13	14.05	1.25						180.000	0.00518	107	25.78	0.15
181.000	0.00112	72	21.41	0.03						181.000	0.04413	13	14.11	1.26						181.000	0.00518	109	25.93	0.15
182.000	0.00107	61	20.07	0.03						182.000	0.04436	11	13.81	1.27						182.000	0.00518	101	25.03	0.15
183.000	0.00104	56	19.35	0.03						183.000	0.04461	12	13.87	1.27						183.000	0.00517	29	16.03	0.15
184.000	9.88019E-4	47	18.33	0.03						184.000	0.04488	14	14.14	1.28						184.000	0.00518	79	22.28	0.15
185.000	9.30729E-4	37	17.04	0.03						185.000	0.04510	12	13.87	1.29						185.000	0.00518	91	23.69	0.15
186.000	8.81168E-4	30	16.15	0.03						186.000	0.04533	12	13.90	1.30						186.000	0.00518	91	23.81	0.15
187.000	8.17381E-4	20	14.98	0.02						187.000	0.04554	11	13.75	1.30						187.000	0.00518	95	24.23	0.15
188.000	7.87360E-4	18	14.65	0.02						188.000	0.04577	12	13.90	1.31						188.000	0.00518	95	24.26	0.15
189.000	8.26848E-4	28	15.94	0.02						189.000	0.04600	12	13.90	1.31						189.000	0.00518	100	24.83	0.15
190.000	9.06820E-4	47	18.27	0.03						190.000	0.04624	12	13.90	1.32						190.000	0.00518	99	24.80	0.15
191.000	9.71578E-4	58	19.68	0.03						191.000	0.04648	12	13.93	1.33						191.000	0.00518	99	24.74	0.15
192.000	0.00103	68	20.93	0.03						192.000	0.04671	12	13.96	1.33						192.000	0.00518	99	24.74	0.15
193.000	0.00109	77	22.04	0.03						193.000	0.04695	12	13.90	1.34
194.000	0.00115	86	23.12	0.03						194.000	0.04719	12	13.87	1.35
195.000	0.00121	95	24.23	0.03						195.000	0.04741	11	13.75	1.35
196.000	0.00123	96	24.32	0.04						196.000	0.04767	13	14.11	1.36
197.000	0.00117	79	22.28	0.03						197.000	0.04791	13	14.08	1.37
198.000	0.00112	68	20.93	0.03						198.000	0.04816	13	14.11	1.38
199.000	0.00107	59	19.83	0.03						199.000	0.04842	13	13.99	1.38
200.000	0.00102	50	18.69	0.03						200.000	0.04869	13	13.99	1.39
201.000	9.58175E-4	40	17.40	0.03						201.000	0.04895	12	13.87	1.40
202.000	9.05091E-4	31	16.30	0.03						202.000	0.04922	12	13.87	1.41
203.000	8.48757E-4	23	15.25	0.02						203.000	0.04944	10	13.72	1.41
204.000	7.97895E-4	16	14.38	0.02						204.000	0.04970	13	13.99	1.42
205.000	8.83739E-4	37	17.04	0.03						205.000	0.04999	13	14.08	1.43
206.000	9.43160E-4	50	18.63	0.03						206.000	0.05024	11	13.84	1.44
207.000	0.00101	62	20.10	0.03						207.000	0.05056	12	13.90	1.44
208.000	0.00107	71	21.32	0.03						208.000	0.05083	11	13.84	1.45
209.000	0.00113	80	22.40	0.03						209.000	0.05110	11	13.84	1.46
210.000	0.00118	87	23.30	0.03						210.000	0.05137	12	13.87	1.47
211.000	0.00123	93	24.05	0.04						211.000	0.05163	10	13.69	1.48
212.000	0.00123	90	23.57	0.04						212.000	0.05187	11	13.78	1.48
213.000	0.00114	70	21.08	0.03						213.000	0.05216	12	13.90	1.49
214.000	0.00111	64	20.40	0.03						214.000	0.05242	12	13.87	1.50
215.000	0.00107	58	19.59	0.03						215.000	0.05264	9	13.57	1.50
216.000	0.00102	48	18.42	0.03						216.000	0.05293	13	13.99	1.51
217.000	9.73292E-4	41	17.49	0.03						217.000	0.05315	9	13.54	1.52
218.000	9.09315E-4	29	16.00	0.03						218.000	0.05342	11	13.75	1.53
219.000	8.54680E-4	21	15.10	0.02						219.000	0.05371	12	13.93	1.53
220.000	8.25928E-4	19	14.77	0.02						220.000	0.05399	11	13.81	1.54
221.000	9.36440E-4	45	17.97	0.03						221.000	0.05421	9	13.60	1.55
222.000	0.00101	58	19.65	0.03						222.000	0.05445	10	13.63	1.56
223.000	0.00108	71	21.29	0.03						223.000	0.05472	11	13.78	1.56
224.000	0.00113	78	22.16	0.03						224.000	0.05499	12	13.90	1.57
225.000	0.00117	85	22.97	0.03						225.000	0.05522	10	13.69	1.58
226.000	0.00120	86	23.15	0.03						226.000	0.05552	12	13.93	1.59
227.000	0.00122	87	23.21	0.03						227.000	0.05579	11	13.81	1.59
228.000	0.00125	91	23.72	0.04						228.000	0.05604	10	13.63	1.60
229.000	0.00125	89	23.45	0.04						229.000	0.05632	11	13.84	1.61
230.000	0.00123	84	22.91	0.04						230.000	0.05658	10	13.69	1.62
231.000	0.00122	80	22.40	0.03						231.000	0.05688	11	13.81	1.63
232.000	0.00121	78	22.13	0.03						232.000	0.05716	12	13.87	1.63
233.000	0.00119	74	21.65	0.03						233.000	0.05741	10	13.72	1.64
234.000	0.00117	71	21.26	0.03						234.000	0.05772	12	13.87	1.65
235.000	0.00116	68	20.90	0.03						235.000	0.05801	12	13.87	1.66
236.000	0.00115	66	20.61	0.03						236.000	0.05826	10	13.69	1.66
237.000	0.00112	61	20.07	0.03						237.000	0.05857	11	13.84	1.67
238.000	0.00109	55	19.23	0.03						238.000	0.05889	12	13.87	1.68
239.000	0.00105	48	18.36	0.03						239.000	0.05916	11	13.78	1.69
240.000	0.00103	46	18.12	0.03						240.000	0.05946	11	13.81	1.70
241.000	0.00101	43	17.82	0.03						241.000	0.05978	13	14.02	1.71
242.000	9.73950E-4	37	17.01	0.03						242.000	0.06004	10	13.63	1.72
243.000	9.45648E-4	32	16.35	0.03						243.000	0.06034	12	13.96	1.72
244.000	9.18964E-4	28	15.91	0.03						244.000	0.06067	10	13.72	1.73
245.000	8.86649E-4	24	15.40	0.03						245.000	0.06093	9	13.57	1.74
246.000	8.52681E-4	18	14.71	0.02						246.000	0.06124	11	13.81	1.75
247.000	8.65142E-4	23	15.34	0.02						247.000	0.06152	9	13.51	1.76
248.000	9.16165E-4	37	17.01	0.03						248.000	0.06172	7	13.27	1.76
249.000	9.42606E-4	42	17.64	0.03						249.000	0.06200	10	13.63	1.77
250.000	9.83677E-4	51	18.72	0.03						250.000	0.06231	12	13.90	1.78
251.000	0.00102	56	19.44	0.03						251.000	0.06256	10	13.63	1.79
252.000	0.00105	61	20.01	0.03						252.000	0.06279	9	13.57	1.79
253.000	0.00109	69	20.99	0.03						253.000	0.06305	10	13.72	1.80
254.000	0.00112	73	21.50	0.03						254.000	0.06332	10	13.63	1.81
255.000	0.00115	75	21.80	0.03						255.000	0.06358	10	13.66	1.82
256.000	0.00118	80	22.40	0.03						256.000	0.06387	11	13.84	1.82
257.000	0.00121	84	22.88	0.03						257.000	0.06417	11	13.75	1.83
258.000	0.00125	90	23.60	0.04						258.000	0.06444	10	13.72	1.84
259.000	0.00127	91	23.72	0.04						259.000	0.06476	12	13.87	1.85
260.000	0.00125	84	22.85	0.04						260.000	0.06504	10	13.72	1.86
261.000	0.00117	67	20.75	0.03						261.000	0.06529	9	13.57	1.87
262.000	0.00113	59	19.77	0.03						262.000	0.06561	12	13.87	1.87
263.000	0.00110	54	19.17	0.03						263.000	0.06588	9	13.60	1.88
264.000	0.00108	53	19.02	0.03						264.000	0.06617	10	13.63	1.89
265.000	0.00107	50	18.66	0.03						265.000	0.06648	11	13.84	1.90
266.000	0.00105	47	18.30	0.03						266.000	0.06671	8	13.48	1.91
267.000	0.00102	43	17.73	0.03						267.000	0.06694	8	13.45	1.91
268.000	9.93512E-4	38	17.10	0.03						268.000	0.06726	12	13.87	1.92
269.000	9.74750E-4	36	16.89	0.03						269.000	0.06756	11	13.75	1.93
270.000	9.39753E-4	29	16.03	0.03						270.000	0.06784	11	13.75	1.94
271.000	8.60167E-4	15	14.35	0.02						271.000	0.06812	11	13.75	1.95
272.000	8.11767E-4	9	13.54	0.02						272.000	0.06842	10	13.72	1.95
273.000	8.11815E-4	12	13.96	0.02						273.000	0.06869	10	13.63	1.96
274.000	8.11523E-4	14	14.17	0.02						274.000	0.06900	10	13.69	1.97
275.000	8.11272E-4	15	14.35	0.02						275.000	0.06929	10	13.69	1.98
276.000	8.11147E-4	16	14.44	0.02						276.000	0.06955	9	13.60	1.99
277.000	8.11021E-4	17	14.53	0.02						277.000	0.06987	11	13.84	2.00
278.000	8.10896E-4	18	14.62	0.02						278.000	0.07013	9	13.51	2.00
279.000	8.10813E-4	18	14.68	0.02						279.000	0.07040	10	13.66	2.01
280.000	8.10730E-4	19	14.74	0.02						280.000	0.07073	11	13.78	2.02
281.000	8.10605E-4	19	14.83	0.02						281.000	0.07096	7	13.36	2.03
										282.000	0.07121	8	13.45	2.03
										283.000	0.07152	10	13.69	2.04
										284.000	0.07179	9	13.57	2.05
										285.000	0.07206	9	13.57	2.06
										286.000	0.07240	11	13.81	2.07
										287.000	0.07270	10	13.72	2.08
										288.000	0.07299	9	13.60	2.09
										289.000	0.07332	11	13.81	2.09
										290.000	0.07356	9	13.54	2.10
										291.000	0.07386	11	13.75	2.11
										292.000	0.07418	11	13.81	2.12
										293.000	0.07447	11	13.84	2.13
										294.000	0.07474	11	13.75	2.14
										295.000	0.07505	11	13.81	2.14
										296.000	0.07529	10	13.63	2.15
										297.000	0.07558	10	13.69	2.16
										298.000	0.07595	12	13.96	2.17
										299.000	0.07626	10	13.72	2.18
										300.000	0.07659	12	13.87	2.19
										301.000	0.07688	10	13.63	2.20
										302.000	0.07716	8	13.39	2.20
										303.000	0.07743	9	13.60	2.21
										304.000	0.07765	8	13.42	2.22
										305.000	0.07793	10	13.66	2.23
										306.000	0.07820	11	13.75	2.23
										307.000	0.07843	8	13.48	2.24
										308.000	0.07873	12	13.90	2.25
										309.000	0.07896	10	13.63	2.26
										310.000	0.07932	13	14.05	2.27
										311.000	0.07968	13	14.02	2.28
										312.000	0.07998	12	13.96	2.29
										313.000	0.08036	15	14.29	2.30
										314.000	0.08061	9	13.54	2.30
										315.000	0.08083	7	13.36	2.31
										316.000	0.08114	11	13.81	2.32
										317.000	0.08143	11	13.75	2.33
										318.000	0.08169	9	13.60	2.33
										319.000	0.08203	12	13.96	2.34
										320.000	0.08242	14	14.23	2.35
										321.000	0.08270	11	13.81	2.36
										322.000	0.08296	10	13.66	2.37
										323.000	0.08328	12	13.96	2.38
										324.000	0.08359	11	13.78	2.39
										325.000	0.08386	10	13.72	2.40
										326.000	0.08418	11	13.81	2.41
										327.000	0.08443	9	13.57	2.41
										328.000	0.08466	8	13.48	2.42
										329.000	0.08506	14	14.23	2.43
										330.000	0.08533	10	13.69	2.44
										331.000	0.08558	9	13.51	2.45
										332.000	0.08587	10	13.66	2.45
										333.000	0.08618	11	13.75	2.46
										334.000	0.08645	9	13.54	2.47
										335.000	0.08677	10	13.69	2.48
										336.000	0.08703	9	13.54	2.49
										337.000	0.08729	9	13.60	2.49
										338.000	0.08759	11	13.78	2.50
										339.000	0.08786	10	13.69	2.51
										340.000	0.08811	8	13.45	2.52
										341.000	0.08833	8	13.48	2.52
										342.000	0.08867	11	13.78	2.53
										343.000	0.08892	9	13.60	2.54
										344.000	0.08915	8	13.48	2.55
										345.000	0.08947	11	13.78	2.56
										346.000	0.08971	9	13.57	2.56
										347.000	0.08990	8	13.45	2.57
										348.000	0.09015	10	13.72	2.58
										349.000	0.09040	10	13.72	2.58
										350.000	0.09060	9	13.51	2.59
										351.000	0.09080	8	13.48	2.59
										352.000	0.09105	11	13.81	2.60
										353.000	0.09129	11	13.78	2.61
										354.000	0.09152	10	13.69	2.61
										355.000	0.09175	11	13.75	2.62
										356.000	0.09202	11	13.78	2.63
										357.000	0.09229	12	13.87	2.64
										358.000	0.09250	10	13.66	2.64
										359.000	0.09277	12	13.96	2.65
										360.000	0.09301	13	13.99	2.66
										361.000	0.09325	11	13.84	2.66
										362.000	0.09350	11	13.81	2.67
										363.000	0.09375	11	13.81	2.68
										364.000	0.09399	11	13.75	2.69
										365.000	0.09422	10	13.69	2.69
										366.000	0.09447	11	13.84	2.70
										367.000	0.09467	10	13.69	2.70
										368.000	0.09491	11	13.75	2.71
										369.000	0.09511	10	13.69	2.72
										370.000	0.09533	11	13.81	2.72
										371.000	0.09558	12	13.96	2.73
										372.000	0.09579	11	13.78	2.74
										373.000	0.09601	11	13.84	2.74
										374.000	0.09626	12	13.90	2.75
										375.000	0.09647	11	13.84	2.76
										376.000	0.09670	11	13.84	2.76
										377.000	0.09691	11	13.84	2.77
										378.000	0.09713	11	13.84	2.78
										379.000	0.09736	12	13.93	2.78
										380.000	0.09756	12	13.87	2.79
										381.000	0.09780	13	14.11	2.79
										382.000	0.09803	13	14.05	2.80
										383.000	0.09825	13	14.05	2.81
										384.000	0.09846	12	13.96	2.81
										385.000	0.09871	13	14.11	2.82
										386.000	0.09892	13	14.02	2.83
										387.000	0.09915	13	13.99	2.83
										388.000	0.09938	13	14.02	2.84
										389.000	0.09961	12	13.93	2.85
										390.000	0.09988	14	14.20	2.85
										391.000	0.10013	14	14.17	2.86
										392.000	0.10039	14	14.20	2.87
										393.000	0.10060	13	14.02	2.87
										394.000	0.10082	13	13.99	2.88
										395.000	0.10112	15	14.29	2.89
										396.000	0.10136	13	14.08	2.90
										397.000	0.10160	13	13.99	2.90
										398.000	0.10183	13	13.99	2.91
										399.000	0.10210	14	14.17	2.92
										400.000	0.10232	12	13.96	2.92
										401.000	0.10258	13	14.08	2.93
										402.000	0.10290	15	14.35	2.94
										403.000	0.10314	13	14.02	2.95
										404.000	0.10336	11	13.81	2.95
										405.000	0.10360	12	13.93	2.96
										406.000	0.10385	12	13.87	2.97
										407.000	0.10406	11	13.75	2.97
										408.000	0.10428	11	13.78	2.98
										409.000	0.10455	13	14.02	2.99
										410.000	0.10478	12	13.87	2.99
										411.000	0.10501	12	13.90	3.00
										412.000	0.10520	11	13.78	3.01
										413.000	0.10551	14	14.23	3.01
										414.000	0.10570	13	13.99	3.02
										415.000	0.10590	12	13.90	3.03
										416.000	0.10610	12	13.93	3.03
										417.000	0.10639	14	14.20	3.04
										418.000	0.10663	14	14.14	3.05
										419.000	0.10684	12	13.96	3.05
										420.000	0.10712	14	14.20	3.06
										421.000	0.10738	14	14.17	3.07
										422.000	0.10764	13	14.11	3.08
										423.000	0.10788	13	14.11	3.08
										424.000	0.10813	14	14.14	3.09
										425.000	0.10847	16	14.47	3.10
										426.000	0.10879	17	14.50	3.11
										427.000	0.10912	16	14.38	3.12
										428.000	0.10943	14	14.17	3.13
										429.000	0.10976	15	14.32	3.14
										430.000	0.11005	13	14.11	3.14
										431.000	0.11036	13	14.05	3.15
										432.000	0.11065	12	13.96	3.16
										433.000	0.11093	13	14.02	3.17
										434.000	0.11121	13	13.99	3.18
										435.000	0.11150	12	13.87	3.19
										436.000	0.11173	11	13.75	3.19
										437.000	0.11202	12	13.90	3.20
										438.000	0.11235	14	14.14	3.21
										439.000	0.11263	14	14.14	3.22
										440.000	0.11291	13	13.99	3.23
										441.000	0.11324	15	14.26	3.24
										442.000	0.11354	13	14.05	3.24
										443.000	0.11381	12	13.93	3.25
										444.000	0.11409	13	13.99	3.26
										445.000	0.11438	13	14.05	3.27
										446.000	0.11463	13	14.02	3.28
										447.000	0.11490	13	14.05	3.28
										448.000	0.11516	13	14.11	3.29
										449.000	0.11538	13	14.02	3.30
										450.000	0.11557	12	13.90	3.30
										451.000	0.11585	16	14.38	3.31
										452.000	0.11617	17	14.53	3.32
										453.000	0.11651	18	14.65	3.33
										454.000	0.11679	16	14.47	3.34
										455.000	0.11710	15	14.32	3.35
										456.000	0.11749	16	14.47	3.36
										457.000	0.11782	15	14.32	3.37
										458.000	0.11816	16	14.41	3.38
										459.000	0.11853	15	14.32	3.39
										460.000	0.11881	13	14.08	3.39
										461.000	0.11911	13	14.02	3.40
										462.000	0.11948	13	14.11	3.41
										463.000	0.11978	13	14.08	3.42
										464.000	0.12010	13	14.02	3.43
										465.000	0.12044	13	14.11	3.44
										466.000	0.12078	14	14.23	3.45
										467.000	0.12110	13	14.11	3.46
										468.000	0.12140	13	14.08	3.47
										469.000	0.12178	14	14.20	3.48
										470.000	0.12209	12	13.90	3.49
										471.000	0.12240	13	14.05	3.50
										472.000	0.12274	13	14.02	3.51
										473.000	0.12303	12	13.96	3.52
										474.000	0.12336	13	14.02	3.52
										475.000	0.12368	13	14.02	3.53
										476.000	0.12398	13	14.02	3.54
										477.000	0.12424	12	13.87	3.55
										478.000	0.12452	11	13.84	3.56
										479.000	0.12479	11	13.84	3.57
										480.000	0.12510	12	13.93	3.57
										481.000	0.12543	13	14.11	3.58
										482.000	0.12577	15	14.26	3.59
										483.000	0.12607	13	14.02	3.60
										484.000	0.12639	13	14.08	3.61
										485.000	0.12673	13	14.08	3.62
										486.000	0.12705	13	13.99	3.63
										487.000	0.12736	12	13.90	3.64
										488.000	0.12754	7	13.30	3.64
										489.000	0.12772	7	13.30	3.65
										490.000	0.12802	11	13.81	3.66
										491.000	0.12825	11	13.78	3.66
										492.000	0.12851	12	13.90	3.67
										493.000	0.12877	13	13.99	3.68
										494.000	0.12900	11	13.84	3.69
										495.000	0.12928	14	14.17	3.69
										496.000	0.12960	15	14.26	3.70
										497.000	0.12992	15	14.26	3.71
										498.000	0.13019	13	14.02	3.72
										499.000	0.13050	14	14.17	3.73
										500.000	0.13082	13	14.08	3.74
										501.000	0.13112	12	13.93	3.75
										502.000	0.13147	13	14.05	3.76
										503.000	0.13181	13	14.08	3.77
										504.000	0.13216	13	14.11	3.78
										505.000	0.13246	12	13.87	3.78
										506.000	0.13285	13	14.05	3.80
										507.000	0.13311	10	13.69	3.80
										508.000	0.13342	11	13.78	3.81
										509.000	0.13370	11	13.84	3.82
										510.000	0.13398	12	13.87	3.83
										511.000	0.13426	12	13.93	3.84
										512.000	0.13450	11	13.84	3.84
										513.000	0.13478	13	13.99	3.85
										514.000	0.13507	13	14.08	3.86
										515.000	0.13539	15	14.26	3.87
										516.000	0.13568	14	14.23	3.88
										517.000	0.13598	14	14.23	3.89
										518.000	0.13626	13	14.05	3.89
										519.000	0.13658	14	14.20	3.90
										520.000	0.13690	14	14.17	3.91
										521.000	0.13723	13	14.02	3.92
										522.000	0.13759	13	14.08	3.93
										523.000	0.13793	12	13.96	3.94
										524.000	0.13825	13	13.99	3.95
										525.000	0.13860	12	13.96	3.96
										526.000	0.13897	12	13.96	3.97
										527.000	0.13934	13	14.02	3.98
										528.000	0.13974	11	13.84	3.99
										529.000	0.14006	10	13.69	4.00
										530.000	0.14041	10	13.69	4.01
										531.000	0.14066	5	13.09	4.02
										532.000	0.14103	9	13.54	4.03
										533.000	0.14133	10	13.72	4.04
										534.000	0.14166	11	13.81	4.05
										535.000	0.14197	10	13.69	4.06
										536.000	0.14228	11	13.78	4.07
										537.000	0.14263	12	13.90	4.08
										538.000	0.14293	10	13.72	4.08
										539.000	0.14329	11	13.81	4.09
										540.000	0.14365	11	13.84	4.10
										541.000	0.14398	11	13.78	4.11
										542.000	0.14429	10	13.72	4.12
										543.000	0.14465	11	13.84	4.13
										544.000	0.14502	12	13.96	4.14
										545.000	0.14538	12	13.90	4.15
										546.000	0.14574	12	13.87	4.16
										547.000	0.14611	12	13.87	4.17
										548.000	0.14644	10	13.69	4.18
										549.000	0.14677	12	13.90	4.19
										550.000	0.14706	11	13.75	4.20
										551.000	0.14733	10	13.72	4.21
										552.000	0.14765	10	13.72	4.22
										553.000	0.14794	10	13.69	4.23
										554.000	0.14826	11	13.84	4.24
										555.000	0.14854	11	13.78	4.24
										556.000	0.14881	10	13.72	4.25
										557.000	0.14906	10	13.69	4.26
										558.000	0.14933	11	13.78	4.27
										559.000	0.14961	11	13.81	4.27
										560.000	0.14994	13	14.05	4.28
										561.000	0.15026	13	14.02	4.29
										562.000	0.15060	13	14.02	4.30
										563.000	0.15096	13	14.05	4.31
										564.000	0.15123	12	13.90	4.32
										565.000	0.15156	12	13.93	4.33
										566.000	0.15190	12	13.87	4.34
										567.000	0.15213	8	13.48	4.35
										568.000	0.15232	7	13.33	4.35
										569.000	0.15260	10	13.63	4.36
										570.000	0.15289	11	13.75	4.37
										571.000	0.15312	10	13.63	4.37
										572.000	0.15344	12	13.90	4.38
										573.000	0.15367	10	13.69	4.39
										574.000	0.15389	9	13.60	4.40
										575.000	0.15418	11	13.81	4.41
										576.000	0.15446	12	13.87	4.41
										577.000	0.15473	11	13.78	4.42
										578.000	0.15498	11	13.81	4.43
										579.000	0.15525	12	13.87	4.44
										580.000	0.15557	13	14.05	4.44
										581.000	0.15589	13	14.11	4.45
										582.000	0.15621	13	14.11	4.46
										583.000	0.15649	12	13.93	4.47
										584.000	0.15680	12	13.93	4.48
										585.000	0.15713	13	14.11	4.49
										586.000	0.15748	14	14.17	4.50
										587.000	0.15778	12	13.93	4.51
										588.000	0.15810	11	13.78	4.52
										589.000	0.15838	11	13.78	4.53
										590.000	0.15869	11	13.84	4.53
										591.000	0.15902	11	13.78	4.54
										592.000	0.15934	11	13.84	4.55
										593.000	0.15964	11	13.75	4.56
										594.000	0.15994	10	13.72	4.57
										595.000	0.16020	10	13.63	4.58
										596.000	0.16054	11	13.84	4.59
										597.000	0.16088	13	13.99	4.60
										598.000	0.16122	12	13.93	4.61
										599.000	0.16157	12	13.90	4.62
										600.000	0.16196	13	14.02	4.63
										601.000	0.16232	11	13.81	4.64
										602.000	0.16264	10	13.63	4.65
										603.000	0.16303	12	13.93	4.66
										604.000	0.16340	12	13.87	4.67
										605.000	0.16371	10	13.72	4.68
										606.000	0.16409	11	13.78	4.69
										607.000	0.16441	10	13.66	4.70
										608.000	0.16477	11	13.75	4.71
										609.000	0.16509	9	13.60	4.72
										610.000	0.16544	11	13.75	4.73
										611.000	0.16582	10	13.72	4.74
										612.000	0.16616	10	13.63	4.75
										613.000	0.16651	10	13.63	4.76
										614.000	0.16685	9	13.57	4.77
										615.000	0.16720	10	13.66	4.78
										616.000	0.16756	11	13.75	4.79
										617.000	0.16787	9	13.57	4.80
										618.000	0.16819	10	13.66	4.81
										619.000	0.16852	10	13.63	4.81
										620.000	0.16889	11	13.75	4.83
										621.000	0.16922	10	13.72	4.83
										622.000	0.16947	8	13.42	4.84
										623.000	0.16977	8	13.45	4.85
										624.000	0.17008	8	13.48	4.86
										625.000	0.17031	7	13.27	4.87
										626.000	0.17055	6	13.21	4.87
										627.000	0.17079	6	13.18	4.88
										628.000	0.17103	7	13.27	4.89
										629.000	0.17128	7	13.33	4.89
										630.000	0.17150	8	13.39	4.90
										631.000	0.17177	9	13.51	4.91
										632.000	0.17205	9	13.57	4.92
										633.000	0.17233	9	13.60	4.92
										634.000	0.17261	9	13.60	4.93
										635.000	0.17286	8	13.45	4.94
										636.000	0.17313	9	13.54	4.95
										637.000	0.17343	10	13.66	4.96
										638.000	0.17368	9	13.54	4.96
										639.000	0.17396	9	13.60	4.97
										640.000	0.17419	8	13.42	4.98
										641.000	0.17446	8	13.48	4.98
										642.000	0.17472	9	13.51	4.99
										643.000	0.17498	9	13.57	5.00
										644.000	0.17522	9	13.51	5.01
										645.000	0.17548	8	13.48	5.01
										646.000	0.17575	9	13.60	5.02
										647.000	0.17603	10	13.66	5.03
										648.000	0.17625	8	13.45	5.04
										649.000	0.17656	10	13.72	5.04
										650.000	0.17683	10	13.69	5.05
										651.000	0.17707	9	13.57	5.06
										652.000	0.17738	11	13.78	5.07
										653.000	0.17762	10	13.69	5.07
										654.000	0.17787	10	13.72	5.08
										655.000	0.17814	10	13.72	5.09
										656.000	0.17836	10	13.63	5.10
										657.000	0.17863	10	13.72	5.10
										658.000	0.17888	10	13.69	5.11
										659.000	0.17902	8	13.42	5.11
										660.000	0.17927	10	13.69	5.12
										661.000	0.17955	12	13.87	5.13
										662.000	0.17977	11	13.81	5.14
										663.000	0.18007	12	13.96	5.14
										664.000	0.18033	12	13.96	5.15
										665.000	0.18062	12	13.96	5.16
										666.000	0.18092	13	13.99	5.17
										667.000	0.18121	13	13.99	5.18
										668.000	0.18148	12	13.93	5.19
										669.000	0.18173	11	13.84	5.19
										670.000	0.18201	11	13.84	5.20
										671.000	0.18229	11	13.84	5.21
										672.000	0.18252	11	13.75	5.21
										673.000	0.18279	10	13.69	5.22
										674.000	0.18306	11	13.78	5.23
										675.000	0.18334	10	13.66	5.24
										676.000	0.18366	11	13.81	5.25
										677.000	0.18391	10	13.66	5.25
										678.000	0.18418	9	13.60	5.26
										679.000	0.18450	10	13.72	5.27
										680.000	0.18474	8	13.48	5.28
										681.000	0.18502	8	13.48	5.29
										682.000	0.18526	7	13.33	5.29
										683.000	0.18556	8	13.45	5.30
										684.000	0.18585	9	13.51	5.31
										685.000	0.18615	9	13.54	5.32
										686.000	0.18644	8	13.48	5.33
										687.000	0.18671	9	13.54	5.33
										688.000	0.18704	10	13.63	5.34
										689.000	0.18734	9	13.57	5.35
										690.000	0.18766	9	13.57	5.36
										691.000	0.18795	9	13.57	5.37
										692.000	0.18824	9	13.51	5.38
										693.000	0.18854	8	13.45	5.39
										694.000	0.18882	8	13.48	5.39
										695.000	0.18907	8	13.42	5.40
										696.000	0.18934	8	13.45	5.41
										697.000	0.18965	9	13.57	5.42
										698.000	0.18990	9	13.54	5.43
										699.000	0.19020	10	13.66	5.43
										700.000	0.19049	10	13.69	5.44
										701.000	0.19078	9	13.60	5.45
										702.000	0.19112	11	13.75	5.46
										703.000	0.19144	10	13.72	5.47
										704.000	0.19170	9	13.57	5.48
										705.000	0.19205	10	13.69	5.49
										706.000	0.19239	10	13.72	5.50
										707.000	0.19271	11	13.75	5.51
										708.000	0.19301	10	13.63	5.51
										709.000	0.19332	9	13.57	5.52
										710.000	0.19364	10	13.63	5.53
										711.000	0.19394	9	13.60	5.54
										712.000	0.19424	10	13.69	5.55
										713.000	0.19455	11	13.75	5.56
										714.000	0.19485	10	13.72	5.57
										715.000	0.19518	11	13.84	5.58
										716.000	0.19552	11	13.84	5.59
										717.000	0.19588	12	13.87	5.60
										718.000	0.19630	12	13.93	5.61
										719.000	0.19666	11	13.78	5.62
										720.000	0.19706	11	13.75	5.63
										721.000	0.19745	10	13.66	5.64
										722.000	0.19781	10	13.63	5.65
										723.000	0.19824	10	13.69	5.66
										724.000	0.19862	9	13.54	5.67
										725.000	0.19892	7	13.30	5.68
										726.000	0.19919	6	13.18	5.69
										727.000	0.19953	7	13.33	5.70
										728.000	0.19983	7	13.30	5.71
										729.000	0.20009	7	13.27	5.72
										730.000	0.20035	7	13.33	5.72
										731.000	0.20060	7	13.27	5.73
										732.000	0.20083	6	13.21	5.74
										733.000	0.20116	8	13.45	5.75
										734.000	0.20143	8	13.42	5.76
										735.000	0.20169	8	13.45	5.76
										736.000	0.20201	10	13.66	5.77
										737.000	0.20227	9	13.57	5.78
										738.000	0.20253	9	13.54	5.79
										739.000	0.20283	10	13.63	5.80
										740.000	0.20307	9	13.54	5.80
										741.000	0.20333	9	13.54	5.81
										742.000	0.20365	11	13.78	5.82
										743.000	0.20394	10	13.72	5.83
										744.000	0.20421	10	13.69	5.83
										745.000	0.20456	12	13.87	5.84
										746.000	0.20482	10	13.69	5.85
										747.000	0.20504	9	13.51	5.86
										748.000	0.20533	10	13.63	5.87
										749.000	0.20558	9	13.60	5.87
										750.000	0.20581	9	13.54	5.88
										751.000	0.20609	10	13.69	5.89
										752.000	0.20637	11	13.84	5.90
										753.000	0.20664	11	13.75	5.90
										754.000	0.20687	10	13.69	5.91
										755.000	0.20714	12	13.87	5.92
										756.000	0.20741	12	13.87	5.93
										757.000	0.20764	11	13.78	5.93
										758.000	0.20795	12	13.96	5.94
										759.000	0.20818	12	13.87	5.95
										760.000	0.20840	11	13.78	5.95
										761.000	0.20871	13	13.99	5.96
										762.000	0.20895	12	13.90	5.97
										763.000	0.20923	12	13.93	5.98
										764.000	0.20952	13	14.05	5.99
										765.000	0.20980	13	14.02	5.99
										766.000	0.21010	13	14.11	6.00
										767.000	0.21036	13	13.99	6.01
										768.000	0.21062	12	13.96	6.02
										769.000	0.21092	13	14.05	6.03
										770.000	0.21118	13	14.02	6.03
										771.000	0.21149	13	14.08	6.04
										772.000	0.21181	14	14.20	6.05
										773.000	0.21208	14	14.17	6.06
										774.000	0.21238	14	14.14	6.07
										775.000	0.21265	13	14.11	6.08
										776.000	0.21294	14	14.20	6.08
										777.000	0.21335	16	14.44	6.10
										778.000	0.21366	15	14.26	6.10
										779.000	0.21398	14	14.17	6.11
										780.000	0.21426	13	14.02	6.12
										781.000	0.21454	13	14.08	6.13
										782.000	0.21483	13	14.02	6.14
										783.000	0.21511	13	14.05	6.15
										784.000	0.21539	13	14.08	6.15
										785.000	0.21568	13	14.02	6.16
										786.000	0.21594	13	13.99	6.17
										787.000	0.21620	12	13.96	6.18
										788.000	0.21651	13	14.11	6.19
										789.000	0.21658	8	13.48	6.19
										790.000	0.21662	5	13.06	6.19
										791.000	0.21663	2	12.73	6.19
										792.000	0.21665	1	12.52	6.19
										793.000	0.21668	0	12.43	6.19
										794.000	0.21669	-1	12.25	6.19
										795.000	0.21674	-1	12.25	6.19
										796.000	0.21674	-2	12.16	6.19
										797.000	0.21683	-1	12.34	6.20
										798.000	0.21687	0	12.37	6.20
										799.000	0.21687	-2	12.22	6.20
										800.000	0.21691	-2	12.22	6.20
										801.000	0.21693	-2	12.19	6.20
										802.000	0.21697	-2	12.22	6.20
										803.000	0.21697	-2	12.13	6.20
										804.000	0.21697	-3	12.07	6.20
										805.000	0.21697	-4	11.99	6.20
										806.000	0.21698	-4	11.93	6.20
										807.000	0.21698	-4	11.90	6.20
										808.000	0.21698	-5	11.81	6.20
										809.000	0.21699	-5	11.78	6.20
										810.000	0.21700	-6	11.72	6.20
										811.000	0.21699	-6	11.66	6.20
										812.000	0.21699	-6	11.63	6.20
										813.000	0.21699	-7	11.60	6.20
										814.000	0.21699	-7	11.54	6.20
										815.000	0.21699	-8	11.42	6.20
										816.000	0.21699	-7	11.51	6.20
										817.000	0.21699	-8	11.45	6.20
										818.000	0.21700	-8	11.48	6.20
										819.000	0.21699	-8	11.45	6.20
										819.800	0.21699	-9	11.36	6.20